[2024-10-16T07:20:38.017+0000] {taskinstance.py:1979} INFO - Dependencies all met for dep_context=non-requeueable deps ti=<TaskInstance: user_automation.stream_data_from_api manual__2024-10-16T07:20:36.502021+00:00 [queued]>
[2024-10-16T07:20:38.027+0000] {taskinstance.py:1979} INFO - Dependencies all met for dep_context=requeueable deps ti=<TaskInstance: user_automation.stream_data_from_api manual__2024-10-16T07:20:36.502021+00:00 [queued]>
[2024-10-16T07:20:38.028+0000] {taskinstance.py:2193} INFO - Starting attempt 1 of 1
[2024-10-16T07:20:38.042+0000] {taskinstance.py:2217} INFO - Executing <Task(PythonOperator): stream_data_from_api> on 2024-10-16 07:20:36.502021+00:00
[2024-10-16T07:20:38.046+0000] {standard_task_runner.py:60} INFO - Started process 185 to run task
[2024-10-16T07:20:38.049+0000] {standard_task_runner.py:87} INFO - Running: ['***', 'tasks', 'run', 'user_automation', 'stream_data_from_api', 'manual__2024-10-16T07:20:36.502021+00:00', '--job-id', '30', '--raw', '--subdir', 'DAGS_FOLDER/my_dag.py', '--cfg-path', '/tmp/tmpf86g9pv_']
[2024-10-16T07:20:38.050+0000] {standard_task_runner.py:88} INFO - Job 30: Subtask stream_data_from_api
[2024-10-16T07:20:38.099+0000] {task_command.py:423} INFO - Running <TaskInstance: user_automation.stream_data_from_api manual__2024-10-16T07:20:36.502021+00:00 [running]> on host 0b70451349c6
[2024-10-16T07:20:38.174+0000] {taskinstance.py:2513} INFO - Exporting env vars: AIRFLOW_CTX_DAG_OWNER='airscholar' AIRFLOW_CTX_DAG_ID='user_automation' AIRFLOW_CTX_TASK_ID='stream_data_from_api' AIRFLOW_CTX_EXECUTION_DATE='2024-10-16T07:20:36.502021+00:00' AIRFLOW_CTX_TRY_NUMBER='1' AIRFLOW_CTX_DAG_RUN_ID='manual__2024-10-16T07:20:36.502021+00:00'
[2024-10-16T07:20:38.176+0000] {taskinstance.py:2731} ERROR - Task failed with exception
Traceback (most recent call last):
  File "/home/airflow/.local/lib/python3.8/site-packages/airflow/models/taskinstance.py", line 444, in _execute_task
    result = _execute_callable(context=context, **execute_callable_kwargs)
  File "/home/airflow/.local/lib/python3.8/site-packages/airflow/models/taskinstance.py", line 414, in _execute_callable
    return execute_callable(context=context, **execute_callable_kwargs)
  File "/home/airflow/.local/lib/python3.8/site-packages/airflow/operators/python.py", line 200, in execute
    return_value = self.execute_callable()
  File "/home/airflow/.local/lib/python3.8/site-packages/airflow/operators/python.py", line 217, in execute_callable
    return self.python_callable(*self.op_args, **self.op_kwargs)
  File "/opt/airflow/dags/my_dag.py", line 39, in stream_data
    from kafka import KafkaProducer
ModuleNotFoundError: No module named 'kafka'
[2024-10-16T07:20:38.191+0000] {taskinstance.py:1149} INFO - Marking task as FAILED. dag_id=user_automation, task_id=stream_data_from_api, execution_date=20241016T072036, start_date=20241016T072038, end_date=20241016T072038
[2024-10-16T07:20:38.206+0000] {standard_task_runner.py:107} ERROR - Failed to execute job 30 for task stream_data_from_api (No module named 'kafka'; 185)
[2024-10-16T07:20:38.222+0000] {local_task_job_runner.py:234} INFO - Task exited with return code 1
[2024-10-16T07:20:38.240+0000] {taskinstance.py:3312} INFO - 0 downstream tasks scheduled from follow-on schedule check
