[2024-12-21T06:29:06.097+0000] {taskinstance.py:1979} INFO - Dependencies all met for dep_context=non-requeueable deps ti=<TaskInstance: user_automation.stream_data_from_api manual__2024-12-21T06:29:05.511623+00:00 [queued]>
[2024-12-21T06:29:06.105+0000] {taskinstance.py:1979} INFO - Dependencies all met for dep_context=requeueable deps ti=<TaskInstance: user_automation.stream_data_from_api manual__2024-12-21T06:29:05.511623+00:00 [queued]>
[2024-12-21T06:29:06.106+0000] {taskinstance.py:2193} INFO - Starting attempt 1 of 1
[2024-12-21T06:29:06.121+0000] {taskinstance.py:2217} INFO - Executing <Task(PythonOperator): stream_data_from_api> on 2024-12-21 06:29:05.511623+00:00
[2024-12-21T06:29:06.129+0000] {standard_task_runner.py:60} INFO - Started process 532 to run task
[2024-12-21T06:29:06.132+0000] {standard_task_runner.py:87} INFO - Running: ['***', 'tasks', 'run', 'user_automation', 'stream_data_from_api', 'manual__2024-12-21T06:29:05.511623+00:00', '--job-id', '34', '--raw', '--subdir', 'DAGS_FOLDER/kafka_streaming.py', '--cfg-path', '/tmp/tmp_61tt2ah']
[2024-12-21T06:29:06.133+0000] {standard_task_runner.py:88} INFO - Job 34: Subtask stream_data_from_api
[2024-12-21T06:29:06.183+0000] {task_command.py:423} INFO - Running <TaskInstance: user_automation.stream_data_from_api manual__2024-12-21T06:29:05.511623+00:00 [running]> on host f6efe59a6eda
[2024-12-21T06:29:06.250+0000] {taskinstance.py:2513} INFO - Exporting env vars: AIRFLOW_CTX_DAG_OWNER='airscholar' AIRFLOW_CTX_DAG_ID='user_automation' AIRFLOW_CTX_TASK_ID='stream_data_from_api' AIRFLOW_CTX_EXECUTION_DATE='2024-12-21T06:29:05.511623+00:00' AIRFLOW_CTX_TRY_NUMBER='1' AIRFLOW_CTX_DAG_RUN_ID='manual__2024-12-21T06:29:05.511623+00:00'
[2024-12-21T06:29:07.327+0000] {conn.py:1527} WARNING - DNS lookup failed for broker:29092, exception was [Errno -2] Name or service not known. Is your advertised.listeners (called advertised.host.name before Kafka 9) correct and resolvable?
[2024-12-21T06:29:07.328+0000] {conn.py:315} ERROR - DNS lookup failed for broker:29092 (0)
[2024-12-21T06:29:07.329+0000] {conn.py:1205} INFO - Probing node bootstrap-0 broker version
[2024-12-21T06:29:07.332+0000] {conn.py:1527} WARNING - DNS lookup failed for broker:29092, exception was [Errno -2] Name or service not known. Is your advertised.listeners (called advertised.host.name before Kafka 9) correct and resolvable?
[2024-12-21T06:29:07.333+0000] {conn.py:315} ERROR - DNS lookup failed for broker:29092 (0)
[2024-12-21T06:29:08.353+0000] {conn.py:1527} WARNING - DNS lookup failed for broker:29092, exception was [Errno -2] Name or service not known. Is your advertised.listeners (called advertised.host.name before Kafka 9) correct and resolvable?
[2024-12-21T06:29:08.354+0000] {conn.py:315} ERROR - DNS lookup failed for broker:29092 (0)
[2024-12-21T06:29:08.354+0000] {conn.py:1205} INFO - Probing node bootstrap-0 broker version
[2024-12-21T06:29:09.369+0000] {conn.py:1527} WARNING - DNS lookup failed for broker:29092, exception was [Errno -2] Name or service not known. Is your advertised.listeners (called advertised.host.name before Kafka 9) correct and resolvable?
[2024-12-21T06:29:09.370+0000] {conn.py:315} ERROR - DNS lookup failed for broker:29092 (0)
[2024-12-21T06:29:09.370+0000] {taskinstance.py:2731} ERROR - Task failed with exception
Traceback (most recent call last):
  File "/home/airflow/.local/lib/python3.8/site-packages/airflow/models/taskinstance.py", line 444, in _execute_task
    result = _execute_callable(context=context, **execute_callable_kwargs)
  File "/home/airflow/.local/lib/python3.8/site-packages/airflow/models/taskinstance.py", line 414, in _execute_callable
    return execute_callable(context=context, **execute_callable_kwargs)
  File "/home/airflow/.local/lib/python3.8/site-packages/airflow/operators/python.py", line 200, in execute
    return_value = self.execute_callable()
  File "/home/airflow/.local/lib/python3.8/site-packages/airflow/operators/python.py", line 217, in execute_callable
    return self.python_callable(*self.op_args, **self.op_kwargs)
  File "/opt/airflow/dags/kafka_streaming.py", line 46, in stream_data
    producer = KafkaProducer(bootstrap_servers=['broker:29092'], max_block_ms=5000)
  File "/home/airflow/.local/lib/python3.8/site-packages/kafka/producer/kafka.py", line 381, in __init__
    client = KafkaClient(metrics=self._metrics, metric_group_prefix='producer',
  File "/home/airflow/.local/lib/python3.8/site-packages/kafka/client_async.py", line 244, in __init__
    self.config['api_version'] = self.check_version(timeout=check_timeout)
  File "/home/airflow/.local/lib/python3.8/site-packages/kafka/client_async.py", line 927, in check_version
    raise Errors.NoBrokersAvailable()
kafka.errors.NoBrokersAvailable: NoBrokersAvailable
[2024-12-21T06:29:09.383+0000] {taskinstance.py:1149} INFO - Marking task as FAILED. dag_id=user_automation, task_id=stream_data_from_api, execution_date=20241221T062905, start_date=20241221T062906, end_date=20241221T062909
[2024-12-21T06:29:09.394+0000] {standard_task_runner.py:107} ERROR - Failed to execute job 34 for task stream_data_from_api (NoBrokersAvailable; 532)
[2024-12-21T06:29:09.438+0000] {local_task_job_runner.py:234} INFO - Task exited with return code 1
[2024-12-21T06:29:09.454+0000] {taskinstance.py:3312} INFO - 0 downstream tasks scheduled from follow-on schedule check
