[2024-10-14T08:31:05.765+0000] {taskinstance.py:1979} INFO - Dependencies all met for dep_context=non-requeueable deps ti=<TaskInstance: user_automation.stream_data_from_api manual__2024-10-14T08:31:04.655018+00:00 [queued]>
[2024-10-14T08:31:05.774+0000] {taskinstance.py:1979} INFO - Dependencies all met for dep_context=requeueable deps ti=<TaskInstance: user_automation.stream_data_from_api manual__2024-10-14T08:31:04.655018+00:00 [queued]>
[2024-10-14T08:31:05.775+0000] {taskinstance.py:2193} INFO - Starting attempt 1 of 1
[2024-10-14T08:31:05.795+0000] {taskinstance.py:2217} INFO - Executing <Task(PythonOperator): stream_data_from_api> on 2024-10-14 08:31:04.655018+00:00
[2024-10-14T08:31:05.802+0000] {standard_task_runner.py:60} INFO - Started process 108 to run task
[2024-10-14T08:31:05.805+0000] {standard_task_runner.py:87} INFO - Running: ['***', 'tasks', 'run', 'user_automation', 'stream_data_from_api', 'manual__2024-10-14T08:31:04.655018+00:00', '--job-id', '6', '--raw', '--subdir', 'DAGS_FOLDER/my_dag.py', '--cfg-path', '/tmp/tmphzmuoq6b']
[2024-10-14T08:31:05.807+0000] {standard_task_runner.py:88} INFO - Job 6: Subtask stream_data_from_api
[2024-10-14T08:31:05.855+0000] {task_command.py:423} INFO - Running <TaskInstance: user_automation.stream_data_from_api manual__2024-10-14T08:31:04.655018+00:00 [running]> on host 5644afbf65e2
[2024-10-14T08:31:05.921+0000] {taskinstance.py:2513} INFO - Exporting env vars: AIRFLOW_CTX_DAG_OWNER='airscholar' AIRFLOW_CTX_DAG_ID='user_automation' AIRFLOW_CTX_TASK_ID='stream_data_from_api' AIRFLOW_CTX_EXECUTION_DATE='2024-10-14T08:31:04.655018+00:00' AIRFLOW_CTX_TRY_NUMBER='1' AIRFLOW_CTX_DAG_RUN_ID='manual__2024-10-14T08:31:04.655018+00:00'
[2024-10-14T08:31:05.924+0000] {taskinstance.py:2731} ERROR - Task failed with exception
Traceback (most recent call last):
  File "/home/airflow/.local/lib/python3.8/site-packages/airflow/models/taskinstance.py", line 444, in _execute_task
    result = _execute_callable(context=context, **execute_callable_kwargs)
  File "/home/airflow/.local/lib/python3.8/site-packages/airflow/models/taskinstance.py", line 414, in _execute_callable
    return execute_callable(context=context, **execute_callable_kwargs)
  File "/home/airflow/.local/lib/python3.8/site-packages/airflow/operators/python.py", line 200, in execute
    return_value = self.execute_callable()
  File "/home/airflow/.local/lib/python3.8/site-packages/airflow/operators/python.py", line 217, in execute_callable
    return self.python_callable(*self.op_args, **self.op_kwargs)
  File "/opt/airflow/dags/my_dag.py", line 39, in stream_data
    from kafka import KafkaProducer
ModuleNotFoundError: No module named 'kafka'
[2024-10-14T08:31:05.936+0000] {taskinstance.py:1149} INFO - Marking task as FAILED. dag_id=user_automation, task_id=stream_data_from_api, execution_date=20241014T083104, start_date=20241014T083105, end_date=20241014T083105
[2024-10-14T08:31:05.950+0000] {standard_task_runner.py:107} ERROR - Failed to execute job 6 for task stream_data_from_api (No module named 'kafka'; 108)
[2024-10-14T08:31:05.978+0000] {local_task_job_runner.py:234} INFO - Task exited with return code 1
[2024-10-14T08:31:05.994+0000] {taskinstance.py:3312} INFO - 0 downstream tasks scheduled from follow-on schedule check
